2024-03-01 13:50:36,330 INFO    StreamThr :44695 [internal.py:wandb_internal():86] W&B internal server running at pid: 44695, started at: 2024-03-01 13:50:36.329429
2024-03-01 13:50:36,333 DEBUG   HandlerThread:44695 [handler.py:handle_request():146] handle_request: status
2024-03-01 13:50:36,339 INFO    WriterThread:44695 [datastore.py:open_for_write():87] open: /mnt/petrelfs/songmingyang/code/mm/MAPO/m3apo/alignment/models/llava-v1_5/wandb/run-20240301_135036-54h06jc2/run-54h06jc2.wandb
2024-03-01 13:50:36,341 DEBUG   SenderThread:44695 [sender.py:send():382] send: header
2024-03-01 13:50:36,716 DEBUG   SenderThread:44695 [sender.py:send():382] send: run
2024-03-01 13:50:41,719 DEBUG   HandlerThread:44695 [handler.py:handle_request():146] handle_request: keepalive
2024-03-01 13:50:46,722 DEBUG   HandlerThread:44695 [handler.py:handle_request():146] handle_request: keepalive
2024-03-01 13:50:51,725 DEBUG   HandlerThread:44695 [handler.py:handle_request():146] handle_request: keepalive
2024-03-01 13:50:56,728 DEBUG   HandlerThread:44695 [handler.py:handle_request():146] handle_request: keepalive
2024-03-01 13:51:01,731 DEBUG   HandlerThread:44695 [handler.py:handle_request():146] handle_request: keepalive
2024-03-01 13:51:06,733 DEBUG   HandlerThread:44695 [handler.py:handle_request():146] handle_request: keepalive
2024-03-01 13:51:11,736 DEBUG   HandlerThread:44695 [handler.py:handle_request():146] handle_request: keepalive
2024-03-01 13:51:16,739 DEBUG   HandlerThread:44695 [handler.py:handle_request():146] handle_request: keepalive
2024-03-01 13:51:21,742 DEBUG   HandlerThread:44695 [handler.py:handle_request():146] handle_request: keepalive
2024-03-01 13:51:26,745 DEBUG   HandlerThread:44695 [handler.py:handle_request():146] handle_request: keepalive
2024-03-01 13:51:31,748 DEBUG   HandlerThread:44695 [handler.py:handle_request():146] handle_request: keepalive
2024-03-01 13:51:36,770 DEBUG   HandlerThread:44695 [handler.py:handle_request():146] handle_request: keepalive
2024-03-01 13:51:41,773 DEBUG   HandlerThread:44695 [handler.py:handle_request():146] handle_request: keepalive
2024-03-01 13:51:42,477 INFO    SenderThread:44695 [retry.py:__call__():172] Retry attempt failed:
Traceback (most recent call last):
  File "/mnt/petrelfs/songmingyang/anaconda3/envs/vcd/lib/python3.9/site-packages/urllib3/connection.py", line 198, in _new_conn
    sock = connection.create_connection(
  File "/mnt/petrelfs/songmingyang/anaconda3/envs/vcd/lib/python3.9/site-packages/urllib3/util/connection.py", line 85, in create_connection
    raise err
  File "/mnt/petrelfs/songmingyang/anaconda3/envs/vcd/lib/python3.9/site-packages/urllib3/util/connection.py", line 73, in create_connection
    sock.connect(sa)
socket.timeout: timed out

The above exception was the direct cause of the following exception:

Traceback (most recent call last):
  File "/mnt/petrelfs/songmingyang/anaconda3/envs/vcd/lib/python3.9/site-packages/urllib3/connectionpool.py", line 793, in urlopen
    response = self._make_request(
  File "/mnt/petrelfs/songmingyang/anaconda3/envs/vcd/lib/python3.9/site-packages/urllib3/connectionpool.py", line 491, in _make_request
    raise new_e
  File "/mnt/petrelfs/songmingyang/anaconda3/envs/vcd/lib/python3.9/site-packages/urllib3/connectionpool.py", line 467, in _make_request
    self._validate_conn(conn)
  File "/mnt/petrelfs/songmingyang/anaconda3/envs/vcd/lib/python3.9/site-packages/urllib3/connectionpool.py", line 1099, in _validate_conn
    conn.connect()
  File "/mnt/petrelfs/songmingyang/anaconda3/envs/vcd/lib/python3.9/site-packages/urllib3/connection.py", line 616, in connect
    self.sock = sock = self._new_conn()
  File "/mnt/petrelfs/songmingyang/anaconda3/envs/vcd/lib/python3.9/site-packages/urllib3/connection.py", line 207, in _new_conn
    raise ConnectTimeoutError(
urllib3.exceptions.ConnectTimeoutError: (<urllib3.connection.HTTPSConnection object at 0x7f6f9f1212b0>, 'Connection to api.wandb.ai timed out. (connect timeout=20)')

The above exception was the direct cause of the following exception:

Traceback (most recent call last):
  File "/mnt/petrelfs/songmingyang/anaconda3/envs/vcd/lib/python3.9/site-packages/requests/adapters.py", line 486, in send
    resp = conn.urlopen(
  File "/mnt/petrelfs/songmingyang/anaconda3/envs/vcd/lib/python3.9/site-packages/urllib3/connectionpool.py", line 847, in urlopen
    retries = retries.increment(
  File "/mnt/petrelfs/songmingyang/anaconda3/envs/vcd/lib/python3.9/site-packages/urllib3/util/retry.py", line 515, in increment
    raise MaxRetryError(_pool, url, reason) from reason  # type: ignore[arg-type]
urllib3.exceptions.MaxRetryError: HTTPSConnectionPool(host='api.wandb.ai', port=443): Max retries exceeded with url: /graphql (Caused by ConnectTimeoutError(<urllib3.connection.HTTPSConnection object at 0x7f6f9f1212b0>, 'Connection to api.wandb.ai timed out. (connect timeout=20)'))

During handling of the above exception, another exception occurred:

Traceback (most recent call last):
  File "/mnt/petrelfs/songmingyang/anaconda3/envs/vcd/lib/python3.9/site-packages/wandb/sdk/lib/retry.py", line 131, in __call__
    result = self._call_fn(*args, **kwargs)
  File "/mnt/petrelfs/songmingyang/anaconda3/envs/vcd/lib/python3.9/site-packages/wandb/sdk/internal/internal_api.py", line 369, in execute
    return self.client.execute(*args, **kwargs)  # type: ignore
  File "/mnt/petrelfs/songmingyang/anaconda3/envs/vcd/lib/python3.9/site-packages/wandb/vendor/gql-0.2.0/wandb_gql/client.py", line 52, in execute
    result = self._get_result(document, *args, **kwargs)
  File "/mnt/petrelfs/songmingyang/anaconda3/envs/vcd/lib/python3.9/site-packages/wandb/vendor/gql-0.2.0/wandb_gql/client.py", line 60, in _get_result
    return self.transport.execute(document, *args, **kwargs)
  File "/mnt/petrelfs/songmingyang/anaconda3/envs/vcd/lib/python3.9/site-packages/wandb/sdk/lib/gql_request.py", line 58, in execute
    request = self.session.post(self.url, **post_args)
  File "/mnt/petrelfs/songmingyang/anaconda3/envs/vcd/lib/python3.9/site-packages/requests/sessions.py", line 637, in post
    return self.request("POST", url, data=data, json=json, **kwargs)
  File "/mnt/petrelfs/songmingyang/anaconda3/envs/vcd/lib/python3.9/site-packages/requests/sessions.py", line 589, in request
    resp = self.send(prep, **send_kwargs)
  File "/mnt/petrelfs/songmingyang/anaconda3/envs/vcd/lib/python3.9/site-packages/requests/sessions.py", line 703, in send
    r = adapter.send(request, **kwargs)
  File "/mnt/petrelfs/songmingyang/anaconda3/envs/vcd/lib/python3.9/site-packages/requests/adapters.py", line 507, in send
    raise ConnectTimeout(e, request=request)
requests.exceptions.ConnectTimeout: HTTPSConnectionPool(host='api.wandb.ai', port=443): Max retries exceeded with url: /graphql (Caused by ConnectTimeoutError(<urllib3.connection.HTTPSConnection object at 0x7f6f9f1212b0>, 'Connection to api.wandb.ai timed out. (connect timeout=20)'))
2024-03-01 13:51:46,776 DEBUG   HandlerThread:44695 [handler.py:handle_request():146] handle_request: keepalive
2024-03-01 13:51:51,779 DEBUG   HandlerThread:44695 [handler.py:handle_request():146] handle_request: keepalive
2024-03-01 13:51:56,782 DEBUG   HandlerThread:44695 [handler.py:handle_request():146] handle_request: keepalive
2024-03-01 13:52:01,784 DEBUG   HandlerThread:44695 [handler.py:handle_request():146] handle_request: keepalive
2024-03-01 13:52:06,787 DEBUG   HandlerThread:44695 [handler.py:handle_request():146] handle_request: cancel
2024-03-01 13:52:06,787 DEBUG   HandlerThread:44695 [handler.py:handle_request():146] handle_request: cancel
2024-03-01 13:52:08,817 DEBUG   HandlerThread:44695 [handler.py:handle_request():146] handle_request: shutdown
2024-03-01 13:52:08,818 INFO    HandlerThread:44695 [handler.py:finish():869] shutting down handler
2024-03-01 13:52:09,788 INFO    WriterThread:44695 [datastore.py:close():296] close: /mnt/petrelfs/songmingyang/code/mm/MAPO/m3apo/alignment/models/llava-v1_5/wandb/run-20240301_135036-54h06jc2/run-54h06jc2.wandb
2024-03-01 13:52:10,480 DEBUG   SenderThread:44695 [sender.py:send():391] Record cancelled: run
2024-03-01 13:52:10,481 INFO    SenderThread:44695 [sender.py:finish():1572] shutting down sender
